<?xml version="1.0" ?>
<!-- =================================================================================== -->
<!-- |    This document was autogenerated by xacro from my_custom_arm.urdf.xacro       | -->
<!-- |    EDITING THIS FILE BY HAND IS NOT RECOMMENDED                                 | -->
<!-- =================================================================================== -->
<robot name="custom_arm">
  <material name="metal_grey">
    <color rgba="0.6 0.6 0.6 1.0"/>
  </material>
  <material name="aluminium_blue">
    <color rgba="0.0 0.3 0.6 1.0"/>
  </material>
  <material name="black">
    <color rgba="0.1 0.1 0.1 1.0"/>
  </material>
  <material name="servo_plastic">
    <color rgba="0.15 0.15 0.15 1.0"/>
  </material>
  <material name="horn_white">
    <color rgba="0.9 0.9 0.9 1.0"/>
  </material>
  <link name="world"/>
  <joint name="world_to_base" type="fixed">
    <parent link="world"/>
    <child link="base_plate_link"/>
    <origin rpy="0 0 0" xyz="0 0 0"/>
  </joint>
  <link name="base_plate_link">
    <visual>
      <geometry>
        <box size="0.3 0.3 0.02"/>
      </geometry>
      <origin rpy="0 0 0" xyz="0 0 0.01"/>
      <material name="metal_grey"/>
    </visual>
    <collision>
      <geometry>
        <box size="0.3 0.3 0.02"/>
      </geometry>
      <origin rpy="0 0 0" xyz="0 0 0.01"/>
    </collision>
    <inertial>
      <mass value="5.0"/>
      <inertia ixx="0.05" ixy="0.0" ixz="0.0" iyy="0.05" iyz="0.0" izz="0.05"/>
    </inertial>
  </link>
  <joint name="base_yaw_joint" type="revolute">
    <parent link="base_plate_link"/>
    <child link="base_yaw_column_link"/>
    <origin rpy="0 0 0" xyz="0 0 0.02"/>
    <axis xyz="0 0 1"/>
    <limit effort="100.0" lower="-3.14159265359" upper="3.14159265359" velocity="1.0"/>
  </joint>
  <link name="base_yaw_column_link">
    <visual>
      <geometry>
        <cylinder length="0.15" radius="0.04"/>
      </geometry>
      <origin rpy="0 0 0" xyz="0 0 0.075"/>
      <material name="metal_grey"/>
    </visual>
    <collision>
      <geometry>
        <cylinder length="0.15" radius="0.04"/>
      </geometry>
      <origin rpy="0 0 0" xyz="0 0 0.075"/>
    </collision>
    <inertial>
      <mass value="3.0"/>
      <inertia ixx="0.03" ixy="0.0" ixz="0.0" iyy="0.03" iyz="0.0" izz="0.03"/>
    </inertial>
  </link>
  <joint name="shoulder_joint" type="revolute">
    <parent link="base_yaw_column_link"/>
    <child link="upper_arm_link"/>
    <origin rpy="0 0 0" xyz="0 0 0.15"/>
    <axis xyz="0 1 0"/>
    <limit effort="150.0" lower="-1.570796326795" upper="1.570796326795" velocity="1.0"/>
  </joint>
  <link name="upper_arm_link">
    <visual>
      <geometry>
        <cylinder length="0.04" radius="0.06"/>
      </geometry>
      <origin rpy="1.5707 0 0" xyz="0 0 0"/>
      <material name="black"/>
    </visual>
    <visual>
      <geometry>
        <box size="0.03 0.015 0.35"/>
      </geometry>
      <origin rpy="0 0 0" xyz="0 0 0.175"/>
      <material name="aluminium_blue"/>
    </visual>
    <collision>
      <geometry>
        <box size="0.05 0.05 0.35"/>
      </geometry>
      <origin rpy="0 0 0" xyz="0 0 0.175"/>
    </collision>
    <inertial>
      <mass value="1.5"/>
      <inertia ixx="0.015" ixy="0.0" ixz="0.0" iyy="0.015" iyz="0.0" izz="0.015"/>
    </inertial>
  </link>
  <joint name="elbow_joint" type="revolute">
    <parent link="upper_arm_link"/>
    <child link="forearm_link"/>
    <origin rpy="0 0 0" xyz="0 0 0.35"/>
    <axis xyz="0 1 0"/>
    <limit effort="100.0" lower="-2.3561944901925003" upper="2.3561944901925003" velocity="1.5"/>
  </joint>
  <link name="forearm_link">
    <visual>
      <geometry>
        <cylinder length="0.03" radius="0.05"/>
      </geometry>
      <origin rpy="1.5707 0 0" xyz="0 0 0"/>
      <material name="black"/>
    </visual>
    <visual>
      <geometry>
        <box size="0.02 0.01 0.35"/>
      </geometry>
      <origin rpy="0 0 0" xyz="0 0 0.175"/>
      <material name="aluminium_blue"/>
    </visual>
    <collision>
      <geometry>
        <box size="0.04 0.04 0.35"/>
      </geometry>
      <origin rpy="0 0 0" xyz="0 0 0.175"/>
    </collision>
    <inertial>
      <mass value="1.0"/>
      <inertia ixx="0.01" ixy="0.0" ixz="0.0" iyy="0.01" iyz="0.0" izz="0.01"/>
    </inertial>
  </link>
  <joint name="wrist_pitch_joint" type="revolute">
    <parent link="forearm_link"/>
    <child link="wrist_bracket_link"/>
    <origin rpy="0 0 0" xyz="0 0 0.35"/>
    <axis xyz="0 1 0"/>
    <limit effort="40.0" lower="-1.570796326795" upper="1.570796326795" velocity="2.0"/>
  </joint>
  <link name="wrist_bracket_link">
    <visual>
      <geometry>
        <box size="0.06 0.08 0.04"/>
      </geometry>
      <origin rpy="0 0 0" xyz="0 0 0.01"/>
      <material name="metal_grey"/>
    </visual>
    <visual>
      <geometry>
        <box size="0.06 0.08 0.01"/>
      </geometry>
      <origin rpy="0 0 0" xyz="0 0 0.07"/>
      <material name="metal_grey"/>
    </visual>
    <collision>
      <geometry>
        <box size="0.08 0.08 0.08"/>
      </geometry>
      <origin rpy="0 0 0" xyz="0 0 0.04"/>
    </collision>
    <inertial>
      <mass value="0.5"/>
      <inertia ixx="0.005" ixy="0.0" ixz="0.0" iyy="0.005" iyz="0.0" izz="0.005"/>
    </inertial>
  </link>
  <joint name="wrist_roll_joint" type="revolute">
    <parent link="wrist_bracket_link"/>
    <child link="wrist_output_shaft_link"/>
    <origin rpy="0 0 0" xyz="0 0 0.07"/>
    <axis xyz="0 0 1"/>
    <limit effort="40.0" lower="-3.14159265359" upper="3.14159265359" velocity="2.0"/>
  </joint>
  <link name="wrist_output_shaft_link">
    <visual>
      <geometry>
        <cylinder length="0.03" radius="0.015"/>
      </geometry>
      <origin rpy="0 0 0" xyz="0 0 0.015"/>
      <material name="metal_grey"/>
    </visual>
    <collision>
      <geometry>
        <cylinder length="0.03" radius="0.015"/>
      </geometry>
      <origin rpy="0 0 0" xyz="0 0 0.015"/>
    </collision>
    <inertial>
      <mass value="0.2"/>
      <inertia ixx="0.002" ixy="0.0" ixz="0.0" iyy="0.002" iyz="0.0" izz="0.002"/>
    </inertial>
  </link>
  <joint name="gripper_mount_joint" type="fixed">
    <parent link="wrist_output_shaft_link"/>
    <child link="gripper_base_link"/>
    <origin rpy="0 0 0" xyz="0 0 0.03"/>
  </joint>
  <link name="gripper_base_link">
    <visual>
      <geometry>
        <box size="0.045 0.06 0.01"/>
      </geometry>
      <origin rpy="0 0 0" xyz="0 0 0.005"/>
      <material name="metal_grey"/>
    </visual>
    <visual>
      <geometry>
        <box size="0.022 0.024 0.032"/>
      </geometry>
      <origin rpy="0 0 0" xyz="-0.005 0 0.026"/>
      <material name="servo_plastic"/>
    </visual>
    <visual>
      <geometry>
        <box size="0.012 0.04 0.075"/>
      </geometry>
      <origin rpy="0 0 0" xyz="0.0175 0 0.065"/>
      <material name="metal_grey"/>
    </visual>
    <collision>
      <geometry>
        <box size="0.06 0.08 0.08"/>
      </geometry>
      <origin rpy="0 0 0" xyz="0 0 0.04"/>
    </collision>
    <inertial>
      <mass value="0.15"/>
      <inertia ixx="0.0015" ixy="0.0" ixz="0.0" iyy="0.0015" iyz="0.0" izz="0.0015"/>
    </inertial>
  </link>
  <joint name="gripper_servo_joint" type="revolute">
    <parent link="gripper_base_link"/>
    <child link="moving_finger_link"/>
    <origin rpy="0 0 0" xyz="-0.005 0 0.035"/>
    <axis xyz="0 1 0"/>
    <limit effort="20.0" lower="-0.6" upper="0.0" velocity="1.0"/>
  </joint>
  <link name="moving_finger_link">
    <visual>
      <geometry>
        <box size="0.008 0.012 0.015"/>
      </geometry>
      <origin rpy="0 0 0" xyz="0 0 0.0025"/>
      <material name="horn_white"/>
    </visual>
    <visual>
      <geometry>
        <box size="0.01 0.06 0.075"/>
      </geometry>
      <origin rpy="0 0 0" xyz="-0.0125 0 0.0325"/>
      <material name="metal_grey"/>
    </visual>
    <visual>
      <geometry>
        <box size="0.04 0.06 0.01"/>
      </geometry>
      <origin rpy="0 0 0" xyz="0.0025 0 -0.01"/>
      <material name="metal_grey"/>
    </visual>
    <visual>
      <geometry>
        <box size="0.012 0.04 0.045"/>
      </geometry>
      <origin rpy="0 0 0" xyz="0 0 0.05"/>
      <material name="metal_grey"/>
    </visual>
    <collision>
      <geometry>
        <box size="0.04 0.06 0.10"/>
      </geometry>
      <origin rpy="0 0 0" xyz="0 0 0.05"/>
    </collision>
    <inertial>
      <mass value="0.1"/>
      <inertia ixx="0.001" ixy="0.0" ixz="0.0" iyy="0.001" iyz="0.0" izz="0.001"/>
    </inertial>
  </link>
  <ros2_control name="CustomArmSystem" type="system">
    <hardware>
      <plugin>gz_ros2_control/GazeboSimSystem</plugin>
    </hardware>
    <joint name="base_yaw_joint">
      <command_interface name="position"/>
      <state_interface name="position"/>
      <state_interface name="velocity"/>
    </joint>
    <joint name="shoulder_joint">
      <command_interface name="position"/>
      <state_interface name="position"/>
      <state_interface name="velocity"/>
    </joint>
    <joint name="elbow_joint">
      <command_interface name="position"/>
      <state_interface name="position"/>
      <state_interface name="velocity"/>
    </joint>
    <joint name="wrist_pitch_joint">
      <command_interface name="position"/>
      <state_interface name="position"/>
      <state_interface name="velocity"/>
    </joint>
    <joint name="wrist_roll_joint">
      <command_interface name="position"/>
      <state_interface name="position"/>
      <state_interface name="velocity"/>
    </joint>
    <joint name="gripper_servo_joint">
      <command_interface name="position"/>
      <state_interface name="position"/>
      <state_interface name="velocity"/>
    </joint>
  </ros2_control>
  <gazebo>
    <plugin filename="libgz_ros2_control-system.so" name="gz_ros2_control::GazeboSimROS2ControlPlugin">
      <parameters>
      /home/koro/ros2_ws/install/arm/share/arm/config/controllers.yaml
    </parameters>
    </plugin>
  </gazebo>
</robot>
